Workbook

Sheet P & L
C3: Planilha de Lucros e Perdas
C5: Descrição | D5: jan | E5: fev | F5: mar | G5: abr | H5: mai | I5: jun | J5: jul | K5: ago | L5: set | M5: out | N5: nov | O5: dez
C7: Receita Liquida | D7: =D9 -> 550000 | E7: =E9 -> 580000 | F7: =F9 -> 620000 | G7: =G9 -> 660000 | H7: =H9 -> 700000 | I7: =I9 -> 730000 | J7: =J9 -> 760000 | K7: =K9 -> 790000 | ... O7: =O9 -> 1080000
C8: R$
C9: area | D9: =SUM(D10:D19) -> 550000 | E9: =SUM(E10:E19) -> 580000 | F9: =SUM(F10:F19) -> 620000 | G9: =SUM(G10:G19) -> 660000 | H9: =SUM(H10:H19) -> 700000 | I9: =SUM(I10:I19) -> 730000 | J9: =SUM(J10:J19) -> 760000 | K9: =SUM(K10:K19) -> 790000 | ... O9: =SUM(O10:O19) -> 1080000
C10: Aparecida | D10: 70000 | E10: 75000 | F10: 80000 | G10: 85000 | H10: 90000 | I10: 95000 | J10: 100000 | K10: 105000 | L10: 110000 | M10: 120000 | N10: 130000 | O10: 150000
C11: Caçapava | D11: 80000 | E11: 85000 | F11: 90000 | G11: 95000 | H11: 100000 | I11: 105000 | J11: 110000 | K11: 115000 | L11: 120000 | M11: 130000 | N11: 140000 | O11: 160000
C12: Jacarei | D12: 120000 | E12: 125000 | F12: 130000 | G12: 140000 | H12: 150000 | I12: 155000 | J12: 160000 | K12: 165000 | L12: 170000 | M12: 180000 | N12: 200000 | O12: 220000
C13: SJC | D13: 180000 | E13: 190000 | F13: 210000 | G13: 220000 | H13: 230000 | I13: 240000 | J13: 250000 | K13: 260000 | L13: 270000 | M13: 280000 | N13: 300000 | O13: 350000
C14: Taubaté | D14: 100000 | E14: 105000 | F14: 110000 | G14: 120000 | H14: 130000 | I14: 135000 | J14: 140000 | K14: 145000 | L14: 150000 | M14: 160000 | N14: 180000 | O14: 200000
D20: jan | E20: fev | F20: mar | G20: abr | H20: mai | I20: jun | J20: jul | K20: ago | L20: set | M20: out | N20: nov | O20: dez
C21: canais | D21: =SUM(D22:D24) -> 550000 | E21: =SUM(E22:E24) -> 580000 | F21: =SUM(F22:F24) -> 620000 | G21: =SUM(G22:G24) -> 660000 | H21: =SUM(H22:H24) -> 700000 | I21: =SUM(I22:I24) -> 730000 | J21: =SUM(J22:J24) -> 760000 | K21: =SUM(K22:K24) -> 790000 | ... O21: =SUM(O22:O24) -> 1080000
C22: diretas | D22: 275000 | E22: 290000 | F22: 310000 | G22: 330000 | H22: 350000 | I22: 365000 | J22: 380000 | K22: 395000 | L22: 410000 | M22: 435000 | N22: 475000 | O22: 540000
C23: e-comerce | D23: 165000 | E23: 174000 | F23: 186000 | G23: 198000 | H23: 210000 | I23: 219000 | J23: 228000 | K23: 237000 | L23: 246000 | M23: 261000 | N23: 285000 | O23: 324000
C24: representantes | D24: 110000 | E24: 116000 | F24: 124000 | G24: 132000 | H24: 140000 | I24: 146000 | J24: 152000 | K24: 158000 | L24: 164000 | M24: 174000 | N24: 190000 | O24: 216000
C26: produtos | D26: =SUM(D27:D31) -> 550000 | E26: =SUM(E27:E31) -> 580000 | F26: =SUM(F27:F31) -> 620000 | G26: =SUM(G27:G31) -> 660000 | H26: =SUM(H27:H31) -> 700000 | I26: =SUM(I27:I31) -> 730000 | J26: =SUM(J27:J31) -> 760000 | K26: =SUM(K27:K31) -> 790000 | ... O26: =SUM(O27:O31) -> 1080000
C27: Conjunto 1 Quarto | D27: 165000 | E27: 174000 | F27: 186000 | G27: 198000 | H27: 210000 | I27: 219000 | J27: 228000 | K27: 237000 | L27: 246000 | M27: 261000 | N27: 285000 | O27: 324000
C28: Conjunto 2 Cozinha | D28: 137500 | E28: 145000 | F28: 155000 | G28: 165000 | H28: 175000 | I28: 182500 | J28: 190000 | K28: 197500 | L28: 205000 | M28: 217500 | N28: 237500 | O28: 270000
C29: Conjunto 3 Sala | D29: 137500 | E29: 145000 | F29: 155000 | G29: 165000 | H29: 175000 | I29: 182500 | J29: 190000 | K29: 197500 | L29: 205000 | M29: 217500 | N29: 237500 | O29: 270000
C30: Conjunto 4 Escritório | D30: 55000 | E30: 58000 | F30: 62000 | G30: 66000 | H30: 70000 | I30: 73000 | J30: 76000 | K30: 79000 | L30: 82000 | M30: 87000 | N30: 95000 | O30: 108000
C31: Conjunto 5 Banheiro | D31: 55000 | E31: 58000 | F31: 62000 | G31: 66000 | H31: 70000 | I31: 73000 | J31: 76000 | K31: 79000 | L31: 82000 | M31: 87000 | N31: 95000 | O31: 108000
C33: qualificação | D33: =SUM(D34:D35) -> 288794.28 | E33: =SUM(E34:E35) -> 300257.3 | F33: =SUM(F34:F35) -> 316379.49 | G33: =SUM(G34:G35) -> 327028.85 | H33: =SUM(H34:H35) -> 341672.1 | I33: =SUM(I34:I35) -> 350916.47 | J33: =SUM(J34:J35) -> 359717.12 | K33: =SUM(K34:K35) -> 368074.63 | ... O33: =SUM(O34:O35) -> 471242.65
C35: Custo das Mercadorias vendidas | D35: =D36 -> 288794.28 | E35: =E36 -> 300257.3 | F35: =F36 -> 316379.49 | G35: =G36 -> 327028.85 | H35: =H36 -> 341672.1 | I35: =I36 -> 350916.47 | J35: =J36 -> 359717.12 | K35: =K36 -> 368074.63 | ... O35: =O36 -> 471242.65
C36: custo das mercadorias vendidas | D36: =D37+D40+D43+D46+D49 -> 288794.28 | E36: =E37+E40+E43+E46+E49 -> 300257.3 | F36: =F37+F40+F43+F46+F49 -> 316379.49 | G36: =G37+G40+G43+G46+G49 -> 327028.85 | H36: =H37+H40+H43+H46+H49 -> 341672.1 | I36: =I37+I40+I43+I46+I49 -> 350916.47 | J36: =J37+J40+J43+J46+J49 -> 359717.12 | K36: =K37+K40+K43+K46+K49 -> 368074.63 | ... O36: =O37+O40+O43+O46+O49 -> 471242.65
C37: Conjunto 1 Quarto | D37: =SUM(D38:D39) -> 86638.283 | E37: =SUM(E38:E39) -> 90077.19 | F37: =SUM(F38:F39) -> 94913.847 | G37: =SUM(G38:G39) -> 98108.703 | H37: =SUM(H38:H39) -> 102501.63 | I37: =SUM(I38:I39) -> 105274.94 | J37: =SUM(J38:J39) -> 107915.14 | K37: =SUM(K38:K39) -> 110422.22 | ... O37: =SUM(O38:O39) -> 141372.38
C38: Guarda Roupas | D38: =D55+D72+D89 -> 51982.97 | E38: =E55+E72+E89 -> 54046.314 | F38: =F55+F72+F89 -> 56948.308 | G38: =G55+G72+G89 -> 58865.222 | H38: =H55+H72+H89 -> 61500.978 | I38: =I55+I72+I89 -> 63164.965 | J38: =J55+J72+J89 -> 64749.082 | K38: =K55+K72+K89 -> 66253.326 | ... O38: =O55+O72+O89 -> 84823.427
C39: Cama | D39: =D56+D73+D90 -> 34655.313 | E39: =E56+E73+E90 -> 36030.876 | F39: =F56+F73+F90 -> 37965.539 | G39: =G56+G73+G90 -> 39243.481 | H39: =H56+H73+H90 -> 41000.652 | I39: =I56+I73+I90 -> 42109.977 | J39: =J56+J73+J90 -> 43166.054 | K39: =K56+K73+K90 -> 44168.897 | ... O39: =O56+O73+O90 -> 56548.951
C40: Conjunto 2 Cozinha | D40: =SUM(D41:D42) -> 72198.569 | E40: =SUM(E41:E42) -> 75064.325 | F40: =SUM(F41:F42) -> 79094.872 | G40: =SUM(G41:G42) -> 81757.253 | H40: =SUM(H41:H42) -> 85418.025 | I40: =SUM(I41:I42) -> 87729.119 | J40: =SUM(J41:J42) -> 89929.28 | K40: =SUM(K41:K42) -> 92018.942 | ... O40: =SUM(O41:O42) -> 117810.32
C41: Armário | D41: =D58+D75+D92 -> 43319.141 | E41: =E58+E75+E92 -> 45038.595 | F41: =F58+F75+F92 -> 47456.924 | G41: =G58+G75+G92 -> 49054.351 | H41: =H58+H75+H92 -> 51250.815 | I41: =I58+I75+I92 -> 52637.471 | J41: =J58+J75+J92 -> 53957.568 | K41: =K58+K75+K92 -> 55211.539 | ... O41: =O58+O75+O92 -> 70686.189
C42: Mesa | D42: =D59+D76+D93 -> 28879.427 | E42: =E59+E76+E93 -> 30025.73 | F42: =F59+F76+F93 -> 31637.949 | G42: =G59+G76+G93 -> 32702.901 | H42: =H59+H76+H93 -> 34167.21 | I42: =I59+I76+I93 -> 35091.647 | J42: =J59+J76+J93 -> 35971.712 | K42: =K59+K76+K93 -> 36807.404 | ... O42: =O59+O76+O93 -> 47124.126
C43: Conjunto 3 Sala | D43: =SUM(D44:D45) -> 72198.569 | E43: =SUM(E44:E45) -> 75064.325 | F43: =SUM(F44:F45) -> 79094.872 | G43: =SUM(G44:G45) -> 81757.253 | H43: =SUM(H44:H45) -> 85418.025 | I43: =SUM(I44:I45) -> 87729.119 | J43: =SUM(J44:J45) -> 89929.28 | K43: =SUM(K44:K45) -> 92018.942 | ... O43: =SUM(O44:O45) -> 117810.32
C44: Sofá | D44: =D61+D78+D95 -> 43319.141 | E44: =E61+E78+E95 -> 45038.595 | F44: =F61+F78+F95 -> 47456.924 | G44: =G61+G78+G95 -> 49054.351 | H44: =H61+H78+H95 -> 51250.815 | I44: =I61+I78+I95 -> 52637.471 | J44: =J61+J78+J95 -> 53957.568 | K44: =K61+K78+K95 -> 55211.539 | ... O44: =O61+O78+O95 -> 70686.189
C45: Painel | D45: =D62+D79+D96 -> 28879.427 | E45: =E62+E79+E96 -> 30025.73 | F45: =F62+F79+F96 -> 31637.949 | G45: =G62+G79+G96 -> 32702.901 | H45: =H62+H79+H96 -> 34167.21 | I45: =I62+I79+I96 -> 35091.647 | J45: =J62+J79+J96 -> 35971.712 | K45: =K62+K79+K96 -> 36807.404 | ... O45: =O62+O79+O96 -> 47124.126
C46: Conjunto 4 Escritório | D46: =SUM(D47:D48) -> 28879.427 | E46: =SUM(E47:E48) -> 30025.73 | F46: =SUM(F47:F48) -> 31637.949 | G46: =SUM(G47:G48) -> 32702.821 | H46: =SUM(H47:H48) -> 34167.21 | I46: =SUM(I47:I48) -> 35091.647 | J46: =SUM(J47:J48) -> 35971.712 | K46: =SUM(K47:K48) -> 36807.259 | ... O46: =SUM(O47:O48) -> 47124.82
C47: Mesa de Escritório | D47: =D64+D81+D98 -> 17327.657 | E47: =E64+E81+E98 -> 18015.438 | F47: =F64+F81+F98 -> 18982.769 | G47: =G64+G81+G98 -> 19621.741 | H47: =H64+H81+H98 -> 20500.326 | I47: =I64+I81+I98 -> 21054.988 | J47: =J64+J81+J98 -> 21583.027 | K47: =K64+K81+K98 -> 22084.298 | ... O47: =O64+O81+O98 -> 28275.169
C48: Cadeira | D48: =D65+D82+D99 -> 11551.771 | E48: =E65+E82+E99 -> 12010.292 | F48: =F65+F82+F99 -> 12655.18 | G48: =G65+G82+G99 -> 13081.08 | H48: =H65+H82+H99 -> 13666.884 | I48: =I65+I82+I99 -> 14036.659 | J48: =J65+J82+J99 -> 14388.685 | K48: =K65+K82+K99 -> 14722.961 | ... O48: =O65+O82+O99 -> 18849.65
C49: Conjunto 5 Banheiro | D49: =SUM(D50:D51) -> 28879.427 | E49: =SUM(E50:E51) -> 30025.73 | F49: =SUM(F50:F51) -> 31637.949 | G49: =SUM(G50:G51) -> 32702.821 | H49: =SUM(H50:H51) -> 34167.21 | I49: =SUM(I50:I51) -> 35091.647 | J49: =SUM(J50:J51) -> 35971.712 | K49: =SUM(K50:K51) -> 36807.259 | ... O49: =SUM(O50:O51) -> 47124.82
C50: Gabinete | D50: =D67+D84+D101 -> 17327.657 | E50: =E67+E84+E101 -> 18015.438 | F50: =F67+F84+F101 -> 18982.769 | G50: =G67+G84+G101 -> 19621.741 | H50: =H67+H84+H101 -> 20500.326 | I50: =I67+I84+I101 -> 21054.988 | J50: =J67+J84+J101 -> 21583.027 | K50: =K67+K84+K101 -> 22084.298 | ... O50: =O67+O84+O101 -> 28275.169
C51: Armarinho | D51: =D68+D85+D102 -> 11551.771 | E51: =E68+E85+E102 -> 12010.292 | F51: =F68+F85+F102 -> 12655.18 | G51: =G68+G85+G102 -> 13081.08 | H51: =H68+H85+H102 -> 13666.884 | I51: =I68+I85+I102 -> 14036.659 | J51: =J68+J85+J102 -> 14388.685 | K51: =K68+K85+K102 -> 14722.961 | ... O51: =O68+O85+O102 -> 18849.65
C53: Materiais | D53: =D54+D57+D60+D63+D66 -> 181582.5 | E53: =E54+E57+E60+E63+E66 -> 188790 | F53: =F54+F57+F60+F63+F66 -> 198927 | G53: =G54+G57+G60+G63+G66 -> 205624.92 | H53: =H54+H57+H60+H63+H66 -> 214830 | I53: =I54+I57+I60+I63+I66 -> 220642.5 | J53: =J54+J57+J60+J63+J66 -> 226176 | K53: =K54+K57+K60+K63+K66 -> 231430.86 | ... O53: =O54+O57+O60+O63+O66 -> 296298
...

Sheet Indicadores Absolutos
B5: Descrisão | C5: ='P & L'!D5 -> jan | D5: ='P & L'!E5 -> fev | E5: ='P & L'!F5 -> mar | F5: ='P & L'!G5 -> abr | G5: ='P & L'!H5 -> mai | H5: ='P & L'!I5 -> jun | I5: ='P & L'!J5 -> jul | J5: ='P & L'!K5 -> ago | ... N5: ='P & L'!O5 -> dez
B6: Receita Total | C6: ='P & L'!D7 -> 550000 | D6: ='P & L'!E7 -> 580000 | E6: ='P & L'!F7 -> 620000 | F6: ='P & L'!G7 -> 660000 | G6: ='P & L'!H7 -> 700000 | H6: ='P & L'!I7 -> 730000 | I6: ='P & L'!J7 -> 760000 | J6: ='P & L'!K7 -> 790000 | ... N6: ='P & L'!O7 -> 1080000
B8: Receita por Área
B9: ='P & L'!C10 -> Aparecida | C9: ='P & L'!D10 -> 70000 | D9: ='P & L'!E10 -> 75000 | E9: ='P & L'!F10 -> 80000 | F9: ='P & L'!G10 -> 85000 | G9: ='P & L'!H10 -> 90000 | H9: ='P & L'!I10 -> 95000 | I9: ='P & L'!J10 -> 100000 | ... N9: ='P & L'!O10 -> 150000
B10: % AP / Total | C10: =C9/C6 -> 0.12727273 | D10: =D9/D6 -> 0.12931034 | E10: =E9/E6 -> 0.12903226 | F10: =F9/F6 -> 0.12878788 | G10: =G9/G6 -> 0.12857143 | H10: =H9/H6 -> 0.13013699 | I10: =I9/I6 -> 0.13157895 | J10: =J9/J6 -> 0.13291139 | ... N10: =N9/N6 -> 0.13888889
B12: ='P & L'!C11 -> Caçapava | C12: ='P & L'!D11 -> 80000 | D12: ='P & L'!E11 -> 85000 | E12: ='P & L'!F11 -> 90000 | F12: ='P & L'!G11 -> 95000 | G12: ='P & L'!H11 -> 100000 | H12: ='P & L'!I11 -> 105000 | I12: ='P & L'!J11 -> 110000 | ... N12: ='P & L'!O11 -> 160000
B13: % CP/ Total | C13: =C12/C6 -> 0.14545455 | D13: =D12/D6 -> 0.14655172 | E13: =E12/E6 -> 0.14516129 | F13: =F12/F6 -> 0.14393939 | G13: =G12/G6 -> 0.14285714 | H13: =H12/H6 -> 0.14383562 | I13: =I12/I6 -> 0.14473684 | J13: =J12/J6 -> 0.14556962 | ... N13: =N12/N6 -> 0.14814815
B15: ='P & L'!C12 -> Jacarei | C15: ='P & L'!D12 -> 120000 | D15: ='P & L'!E12 -> 125000 | E15: ='P & L'!F12 -> 130000 | F15: ='P & L'!G12 -> 140000 | G15: ='P & L'!H12 -> 150000 | H15: ='P & L'!I12 -> 155000 | I15: ='P & L'!J12 -> 160000 | ... N15: ='P & L'!O12 -> 220000
B16: % JC / Total | C16: =C15/C6 -> 0.21818182 | D16: =D15/D6 -> 0.21551724 | E16: =E15/E6 -> 0.20967742 | F16: =F15/F6 -> 0.21212121 | G16: =G15/G6 -> 0.21428571 | H16: =H15/H6 -> 0.21232877 | I16: =I15/I6 -> 0.21052632 | J16: =J15/J6 -> 0.20886076 | ... N16: =N15/N6 -> 0.2037037
B18: ='P & L'!C13 -> SJC | C18: ='P & L'!D13 -> 180000 | D18: ='P & L'!E13 -> 190000 | E18: ='P & L'!F13 -> 210000 | F18: ='P & L'!G13 -> 220000 | G18: ='P & L'!H13 -> 230000 | H18: ='P & L'!I13 -> 240000 | I18: ='P & L'!J13 -> 250000 | ... N18: ='P & L'!O13 -> 350000
B19: % SJC / Total | C19: =C18/C6 -> 0.32727273 | D19: =D18/D6 -> 0.32758621 | E19: =E18/E6 -> 0.33870968 | F19: =F18/F6 -> 0.33333333 | G19: =G18/G6 -> 0.32857143 | H19: =H18/H6 -> 0.32876712 | I19: =I18/I6 -> 0.32894737 | J19: =J18/J6 -> 0.32911392 | ... N19: =N18/N6 -> 0.32407407
B21: ='P & L'!C14 -> Taubaté | C21: ='P & L'!D14 -> 100000 | D21: ='P & L'!E14 -> 105000 | E21: ='P & L'!F14 -> 110000 | F21: ='P & L'!G14 -> 120000 | G21: ='P & L'!H14 -> 130000 | H21: ='P & L'!I14 -> 135000 | I21: ='P & L'!J14 -> 140000 | ... N21: ='P & L'!O14 -> 200000
B22: % TE/ Total | C22: =C21/C6 -> 0.18181818 | D22: =D21/D6 -> 0.18103448 | E22: =E21/E6 -> 0.17741935 | F22: =F21/F6 -> 0.18181818 | G22: =G21/G6 -> 0.18571429 | H22: =H21/H6 -> 0.18493151 | I22: =I21/I6 -> 0.18421053 | J22: =J21/J6 -> 0.1835443 | ... N22: =N21/N6 -> 0.18518519
B30: ='P & L'!C22 -> diretas | C30: ='P & L'!D22 -> 275000 | D30: ='P & L'!E22 -> 290000 | E30: ='P & L'!F22 -> 310000 | F30: ='P & L'!G22 -> 330000 | G30: ='P & L'!H22 -> 350000 | H30: ='P & L'!I22 -> 365000 | I30: ='P & L'!J22 -> 380000 | ... N30: ='P & L'!O22 -> 540000
B31: % vendas diretas / total | C31: =C30/C6 -> 0.5 | D31: =D30/D6 -> 0.5 | E31: =E30/E6 -> 0.5 | F31: =F30/F6 -> 0.5 | G31: =G30/G6 -> 0.5 | H31: =H30/H6 -> 0.5 | I31: =I30/I6 -> 0.5 | J31: =J30/J6 -> 0.5 | ... N31: =N30/N6 -> 0.5
B32: ='P & L'!C23 -> e-comerce | C32: ='P & L'!D23 -> 165000 | D32: ='P & L'!E23 -> 174000 | E32: ='P & L'!F23 -> 186000 | F32: ='P & L'!G23 -> 198000 | G32: ='P & L'!H23 -> 210000 | H32: ='P & L'!I23 -> 219000 | I32: ='P & L'!J23 -> 228000 | ... N32: ='P & L'!O23 -> 324000
B33: % Vendas e-comerce / total | C33: =C32/C6 -> 0.3 | D33: =D32/D6 -> 0.3 | E33: =E32/E6 -> 0.3 | F33: =F32/F6 -> 0.3 | G33: =G32/G6 -> 0.3 | H33: =H32/H6 -> 0.3 | I33: =I32/I6 -> 0.3 | J33: =J32/J6 -> 0.3 | ... N33: =N32/N6 -> 0.3
B34: ='P & L'!C24 -> representantes | C34: ='P & L'!D24 -> 110000 | D34: ='P & L'!E24 -> 116000 | E34: ='P & L'!F24 -> 124000 | F34: ='P & L'!G24 -> 132000 | G34: ='P & L'!H24 -> 140000 | H34: ='P & L'!I24 -> 146000 | I34: ='P & L'!J24 -> 152000 | ... N34: ='P & L'!O24 -> 216000
B35: % representantes / Total | C35: =C34/C6 -> 0.2 | D35: =D34/D6 -> 0.2 | E35: =E34/E6 -> 0.2 | F35: =F34/F6 -> 0.2 | G35: =G34/G6 -> 0.2 | H35: =H34/H6 -> 0.2 | I35: =I34/I6 -> 0.2 | J35: =J34/J6 -> 0.2 | ... N35: =N34/N6 -> 0.2
B44: ='P & L'!C35 -> Custo das Mercadorias vendidas | C44: ='P & L'!D35 -> 288794.28 | D44: ='P & L'!E35 -> 300257.3 | E44: ='P & L'!F35 -> 316379.49 | F44: ='P & L'!G35 -> 327028.85 | G44: ='P & L'!H35 -> 341672.1 | H44: ='P & L'!I35 -> 350916.47 | I44: ='P & L'!J35 -> 359717.12 | ... N44: ='P & L'!O35 -> 471242.65
B45: ='P & L'!C53 -> Materiais | C45: ='P & L'!D53 -> 181582.5 | D45: ='P & L'!E53 -> 188790 | E45: ='P & L'!F53 -> 198927 | F45: ='P & L'!G53 -> 205624.92 | G45: ='P & L'!H53 -> 214830 | H45: ='P & L'!I53 -> 220642.5 | I45: ='P & L'!J53 -> 226176 | ... N45: ='P & L'!O53 -> 296298
B46: Materiais / CMV | C46: =C45/C44 -> 0.62876073 | D46: =D45/D44 -> 0.62876073 | E46: =E45/E44 -> 0.62876073 | F46: =F45/F44 -> 0.62876691 | G46: =G45/G44 -> 0.62876073 | H46: =H45/H44 -> 0.62876073 | I46: =I45/I44 -> 0.62876073 | J46: =J45/J44 -> 0.6287607 | ... N46: =N45/N44 -> 0.62875888
B47: ='P & L'!C70 -> mão de obra direta | C47: ='P & L'!D70 -> 56427.25 | D47: ='P & L'!E70 -> 58667 | E47: ='P & L'!F70 -> 61817.1 | F47: ='P & L'!G70 -> 63897.9 | G47: ='P & L'!H70 -> 66759 | H47: ='P & L'!I70 -> 68565.25 | I47: ='P & L'!J70 -> 70284.8 | ... N47: ='P & L'!O70 -> 92075.4
B48: MOD / CMV | C48: =C47/C44 -> 0.19538909 | D48: =D47/D44 -> 0.19538909 | E48: =E47/E44 -> 0.19538909 | F48: =F47/F44 -> 0.19538918 | G48: =G47/G44 -> 0.19538909 | H48: =H47/H44 -> 0.19538909 | I48: =I47/I44 -> 0.19538909 | J48: =J47/J44 -> 0.19538877 | ... N48: =N47/N44 -> 0.19538851
B49: ='P & L'!C87 -> custos indiretos | C49: ='P & L'!D87 -> 50784.525 | D49: ='P & L'!E87 -> 52800.3 | E49: ='P & L'!F87 -> 55635.39 | F49: ='P & L'!G87 -> 57506.029 | G49: ='P & L'!H87 -> 60083.1 | H49: ='P & L'!I87 -> 61708.725 | I49: ='P & L'!J87 -> 63256.32 | ... N49: ='P & L'!O87 -> 82869.247
B50: CI / CMV | C50: =C49/C44 -> 0.17585018 | D50: =D49/D44 -> 0.17585018 | E50: =E49/E44 -> 0.17585018 | F50: =F49/F44 -> 0.1758439 | G50: =G49/G44 -> 0.17585018 | H50: =H49/H44 -> 0.17585018 | I50: =I49/I44 -> 0.17585018 | J50: =J49/J44 -> 0.17585052 | ... N50: =N49/N44 -> 0.17585261
B72: ='P & L'!C104 -> Lucro Bruto | C72: ='P & L'!D104 -> 261205.72 | D72: ='P & L'!E104 -> 279742.7 | E72: ='P & L'!F104 -> 303620.51 | F72: ='P & L'!G104 -> 332971.15 | G72: ='P & L'!H104 -> 358327.9 | H72: ='P & L'!I104 -> 379083.53 | I72: ='P & L'!J104 -> 400282.88 | ... N72: ='P & L'!O104 -> 608757.35
B73: ='P & L'!C107 -> Conjunto 1 Quarto | C73: ='P & L'!D107 -> 78361.717 | D73: ='P & L'!E107 -> 83922.81 | E73: ='P & L'!F107 -> 91086.153 | F73: ='P & L'!G107 -> 99891.297 | G73: ='P & L'!H107 -> 107498.37 | H73: ='P & L'!I107 -> 113725.06 | I73: ='P & L'!J107 -> 120084.86 | ... N73: ='P & L'!O107 -> 182627.62
B74: LB fam1 / LB | C74: =C73/C72 -> 0.3 | D74: =D73/D72 -> 0.3 | E74: =E73/E72 -> 0.3 | F74: =F73/F72 -> 0.29999986 | G74: =G73/G72 -> 0.3 | H74: =H73/H72 -> 0.3 | I74: =I73/I72 -> 0.3 | J74: =J73/J72 -> 0.30000039 | ... N74: =N73/N72 -> 0.30000068
B75: ='P & L'!C108 -> Conjunto 2 Cozinha | C75: ='P & L'!D108 -> 65301.431 | D75: ='P & L'!E108 -> 69935.675 | E75: ='P & L'!F108 -> 75905.128 | F75: ='P & L'!G108 -> 83242.747 | G75: ='P & L'!H108 -> 89581.975 | H75: ='P & L'!I108 -> 94770.881 | I75: ='P & L'!J108 -> 100070.72 | ... N75: ='P & L'!O108 -> 152189.68
B76: LB fam2 / LB | C76: =C75/C72 -> 0.25 | D76: =D75/D72 -> 0.25 | E76: =E75/E72 -> 0.25 | F76: =F75/F72 -> 0.24999988 | G76: =G75/G72 -> 0.25 | H76: =H75/H72 -> 0.25 | I76: =I75/I72 -> 0.25 | J76: =J75/J72 -> 0.24999932 | ... N76: =N75/N72 -> 0.25000057
B77: ='P & L'!C109 -> Conjunto 3 Sala | C77: ='P & L'!D109 -> 65301.431 | D77: ='P & L'!E109 -> 69935.675 | E77: ='P & L'!F109 -> 75905.128 | F77: ='P & L'!G109 -> 83242.747 | G77: ='P & L'!H109 -> 89581.975 | H77: ='P & L'!I109 -> 94770.881 | I77: ='P & L'!J109 -> 100070.72 | ... N77: ='P & L'!O109 -> 152189.68
B78: LB fam 3 / LB | C78: =C77/C72 -> 0.25 | D78: =D77/D72 -> 0.25 | E78: =E77/E72 -> 0.25 | F78: =F77/F72 -> 0.24999988 | G78: =G77/G72 -> 0.25 | H78: =H77/H72 -> 0.25 | I78: =I77/I72 -> 0.25 | J78: =J77/J72 -> 0.24999932 | ... N78: =N77/N72 -> 0.25000057
B79: ='P & L'!C110 -> Conjunto 4 Escritório | C79: ='P & L'!D110 -> 26120.573 | D79: ='P & L'!E110 -> 27974.27 | E79: ='P & L'!F110 -> 30362.051 | F79: ='P & L'!G110 -> 33297.179 | G79: ='P & L'!H110 -> 35832.79 | H79: ='P & L'!I110 -> 37908.353 | I79: ='P & L'!J110 -> 40028.288 | ... N79: ='P & L'!O110 -> 60875.18
B80: LB fam 4 / LB | C80: =C79/C72 -> 0.1 | D80: =D79/D72 -> 0.1 | E80: =E79/E72 -> 0.1 | F80: =F79/F72 -> 0.10000019 | G80: =G79/G72 -> 0.1 | H80: =H79/H72 -> 0.1 | I80: =I79/I72 -> 0.1 | J80: =J79/J72 -> 0.10000048 | ... N80: =N79/N72 -> 0.099999089
B81: ='P & L'!C111 -> Conjunto 5 Banheiro | C81: ='P & L'!D111 -> 26120.573 | D81: ='P & L'!E111 -> 27974.27 | E81: ='P & L'!F111 -> 30362.051 | F81: ='P & L'!G111 -> 33297.179 | G81: ='P & L'!H111 -> 35832.79 | H81: ='P & L'!I111 -> 37908.353 | I81: ='P & L'!J111 -> 40028.288 | ... N81: ='P & L'!O111 -> 60875.18
B82: LB fam 5 / LB | C82: =C81/C72 -> 0.1 | D82: =D81/D72 -> 0.1 | E82: =E81/E72 -> 0.1 | F82: =F81/F72 -> 0.10000019 | G82: =G81/G72 -> 0.1 | H82: =H81/H72 -> 0.1 | I82: =I81/I72 -> 0.1 | J82: =J81/J72 -> 0.10000048 | ... N82: =N81/N72 -> 0.099999089

Sheet Indicadores Relativos
C5: ='P & L'!C5:O5 -> Descrição | D5: ='P & L'!D5 -> jan | E5: ='P & L'!E5 -> fev | F5: ='P & L'!F5 -> mar | G5: ='P & L'!G5 -> abr | H5: ='P & L'!H5 -> mai | I5: ='P & L'!I5 -> jun | J5: ='P & L'!J5 -> jul | K5: ='P & L'!K5 -> ago | ... O5: ='P & L'!O5 -> dez | Q5: ano 0 | T5: ano 1 | V5: ano 2
C7: ='P & L'!C7 -> Receita Liquida | D7: ='P & L'!D7 -> 550000 | E7: ='P & L'!E7 -> 580000 | F7: ='P & L'!F7 -> 620000 | G7: ='P & L'!G7 -> 660000 | H7: ='P & L'!H7 -> 700000 | I7: ='P & L'!I7 -> 730000 | J7: ='P & L'!J7 -> 760000 | ... O7: ='P & L'!O7 -> 1080000 | P7: RL | Q7: =SUM(D7:O7) -> 9110000 | T7: =Q7*T8 -> 10021000 | V7: =T7*V8 -> 10722470
T8: 1.1 | V8: 1.07
C9: ='P & L'!C35 -> Custo das Mercadorias vendidas | D9: ='P & L'!D35 -> 288794.28 | E9: ='P & L'!E35 -> 300257.3 | F9: ='P & L'!F35 -> 316379.49 | G9: ='P & L'!G35 -> 327028.85 | H9: ='P & L'!H35 -> 341672.1 | I9: ='P & L'!I35 -> 350916.47 | J9: ='P & L'!J35 -> 359717.12 | ... O9: ='P & L'!O35 -> 471242.65 | P9: CMV | Q9: =SUM(D9:O9) -> 4314092.8 | R9: CMV/RL | S9: =Q9/Q7 -> 0.47355574 | T9: =Q9*T10 -> 4702361.2 | U9: =T9/T7 -> 0.46925069 | V9: =T9*V10 -> 4984502.8
C10: CMV / RL | D10: =D9/D7 -> 0.5250805 | E10: =E9/E7 -> 0.517685 | F10: =F9/F7 -> 0.5102895 | G10: =G9/G7 -> 0.49549826 | H10: =H9/H7 -> 0.488103 | I10: =I9/I7 -> 0.4807075 | J10: =J9/J7 -> 0.473312 | K10: =K9/K7 -> 0.46591725 | ... O10: =O9/O7 -> 0.43633578 | T10: 1.09 | V10: 1.06
C11: ='P & L'!C104 -> Lucro Bruto | D11: ='P & L'!D104 -> 261205.72 | E11: ='P & L'!E104 -> 279742.7 | F11: ='P & L'!F104 -> 303620.51 | G11: ='P & L'!G104 -> 332971.15 | H11: ='P & L'!H104 -> 358327.9 | I11: ='P & L'!I104 -> 379083.53 | J11: ='P & L'!J104 -> 400282.88 | ... O11: ='P & L'!O104 -> 608757.35 | P11: LB | Q11: =SUM(D11:O11) -> 4795907.2 | R11: LB/RL | S11: =Q11/Q7 -> 0.52644426 | T11: =T7-T9 -> 5318638.8 | U11: =T11/T7 -> 0.53074931 | V11: =V7-V9 -> 5737967.2
C12: LB / RL | D12: =D11/D7 -> 0.4749195 | E12: =E11/E7 -> 0.482315 | F12: =F11/F7 -> 0.4897105 | G12: =G11/G7 -> 0.50450174 | H12: =H11/H7 -> 0.511897 | I12: =I11/I7 -> 0.5192925 | J12: =J11/J7 -> 0.526688 | K12: =K11/K7 -> 0.53408275 | ... O12: =O11/O7 -> 0.56366422
C13: ='P & L'!C113 -> Despesas Administrativas e Comerciais | D13: ='P & L'!D113 -> 165000 | E13: ='P & L'!E113 -> 174000 | F13: ='P & L'!F113 -> 186000 | G13: ='P & L'!G113 -> 198000 | H13: ='P & L'!H113 -> 210000 | I13: ='P & L'!I113 -> 219000 | J13: ='P & L'!J113 -> 228000 | ... O13: ='P & L'!O113 -> 324000 | P13: DAC | Q13: =SUM(D13:O13) -> 2733000 | R13: DAC/RL | S13: =Q13/Q7 -> 0.3 | T13: =Q13*T14 -> 2951640 | U13: =T13/T7 -> 0.29454545 | V13: =T13*V14 -> 3187771.2
C14: DAC / RL | D14: =D13/D7 -> 0.3 | E14: =E13/E7 -> 0.3 | F14: =F13/F7 -> 0.3 | G14: =G13/G7 -> 0.3 | H14: =H13/H7 -> 0.3 | I14: =I13/I7 -> 0.3 | J14: =J13/J7 -> 0.3 | K14: =K13/K7 -> 0.3 | ... O14: =O13/O7 -> 0.3 | T14: 1.08 | V14: 1.08
C15: ='P & L'!C130 -> Outras despesas / receitas | D15: ='P & L'!D130 -> 1500 | E15: ='P & L'!E130 -> 1570 | F15: ='P & L'!F130 -> 1650 | G15: ='P & L'!G130 -> 1730 | H15: ='P & L'!H130 -> 1800 | I15: ='P & L'!I130 -> 1870 | J15: ='P & L'!J130 -> 1950 | ... O15: ='P & L'!O130 -> 2700 | P15: outras | Q15: =SUM(D15:O15) -> 23550 | T15: =Q15 -> 23550 | V15: =T15 -> 23550
C17: ='P & L'!C136 -> Lucro Liquido | D17: ='P & L'!D136 -> 97705.725 | E17: ='P & L'!E136 -> 107312.7 | F17: ='P & L'!F136 -> 119270.51 | G17: ='P & L'!G136 -> 136701.15 | H17: ='P & L'!H136 -> 150127.9 | I17: ='P & L'!I136 -> 161953.53 | J17: ='P & L'!J136 -> 174232.88 | ... O17: ='P & L'!O136 -> 287457.35 | P17: LL | Q17: =SUM(D17:O17) -> 2086457.2 | R17: LL/RL | S17: =Q17/Q7 -> 0.22902933 | T17: =T11-T13+T15 -> 2390548.8 | V17: =V11-V13+V15 -> 2573746
C18: LL / RL | D18: =D17/D7 -> 0.17764677 | E18: =E17/E7 -> 0.1850219 | F18: =F17/F7 -> 0.19237179 | G18: =G17/G7 -> 0.20712296 | H18: =H17/H7 -> 0.21446843 | I18: =I17/I7 -> 0.22185414 | J18: =J17/J7 -> 0.22925379 | K18: =K17/K7 -> 0.23665237 | ... O18: =O17/O7 -> 0.26616422 | T18: =T17/Q17 -> 1.1457455 | V18: =V17/T17 -> 1.0766339
V20: =V17/Q17 -> 1.2335484
D87: Descrição | E87: jan | F87: fev | G87: mar | H87: abr | I87: mai | J87: jun | K87: jul | L87: ago | M87: set | N87: out | O87: nov | P87: dez
D89: Receita Liquida | E89: ='P & L'!D7 -> 550000 | F89: ='P & L'!E7 -> 580000 | G89: ='P & L'!F7 -> 620000 | H89: ='P & L'!G7 -> 660000 | I89: ='P & L'!H7 -> 700000 | J89: ='P & L'!I7 -> 730000 | K89: ='P & L'!J7 -> 760000 | L89: ='P & L'!K7 -> 790000 | ... P89: ='P & L'!O7 -> 1080000
D90: CMV | E90: =D9 -> 288794.28 | F90: =E9 -> 300257.3 | G90: =F9 -> 316379.49 | H90: =G9 -> 327028.85 | I90: =H9 -> 341672.1 | J90: =I9 -> 350916.47 | K90: =J9 -> 359717.12 | L90: =K9 -> 368074.63 | ... P90: =O9 -> 471242.65
D91: Estoques mensais | E91: =E92+E96+E100+E104+E108 -> 433200 | F91: =F92+F96+F100+F104+F108 -> 456400 | G91: =G92+G96+G100+G104+G108 -> 487200 | H91: =H92+H96+H100+H104+H108 -> 510200 | I91: =I92+I96+I100+I104+I108 -> 539800 | J91: =J92+J96+J100+J104+J108 -> 561500 | K91: =K92+K96+K100+K104+K108 -> 582700 | L91: =L92+L96+L100+L104+L108 -> 603600 | ... P91: =P92+P96+P100+P104+P108 -> 895400
D92: Conjunto 1 Quarto | E92: =SUM(E94:E95) -> 108300 | F92: =SUM(F94:F95) -> 114100 | G92: =SUM(G94:G95) -> 121800 | H92: =SUM(H94:H95) -> 127550 | I92: =SUM(I94:I95) -> 134950 | J92: =SUM(J94:J95) -> 140375 | K92: =SUM(K94:K95) -> 145675 | L92: =SUM(L94:L95) -> 150900 | ... P92: =SUM(P94:P95) -> 223850
D93: % conj 1 / E | E93: =E92/E91 -> 0.25 | F93: =F92/F91 -> 0.25 | G93: =G92/G91 -> 0.25 | H93: =H92/H91 -> 0.25 | I93: =I92/I91 -> 0.25 | J93: =J92/J91 -> 0.25 | K93: =K92/K91 -> 0.25 | L93: =L92/L91 -> 0.25 | ... P93: =P92/P91 -> 0.25
D94: Guarda Roupas (15%) | E94: ='P & L'!D142 -> 64980 | F94: ='P & L'!E142 -> 68460 | G94: ='P & L'!F142 -> 73080 | H94: ='P & L'!G142 -> 76530 | I94: ='P & L'!H142 -> 80970 | J94: ='P & L'!I142 -> 84225 | K94: ='P & L'!J142 -> 87405 | L94: ='P & L'!K142 -> 90540 | ... P94: ='P & L'!O142 -> 134310
D95: Cama (10%) | E95: ='P & L'!D143 -> 43320 | F95: ='P & L'!E143 -> 45640 | G95: ='P & L'!F143 -> 48720 | H95: ='P & L'!G143 -> 51020 | I95: ='P & L'!H143 -> 53980 | J95: ='P & L'!I143 -> 56150 | K95: ='P & L'!J143 -> 58270 | L95: ='P & L'!K143 -> 60360 | ... P95: ='P & L'!O143 -> 89540
D96: Conjunto 2 Cozinha | E96: =SUM(E98:E99) -> 95304 | F96: =SUM(F98:F99) -> 100408 | G96: =SUM(G98:G99) -> 107184 | H96: =SUM(H98:H99) -> 112244 | I96: =SUM(I98:I99) -> 118756 | J96: =SUM(J98:J99) -> 123530 | K96: =SUM(K98:K99) -> 128194 | L96: =SUM(L98:L99) -> 132792 | ... P96: =SUM(P98:P99) -> 196988
D97: % conj 2 / E | E97: =E96/E91 -> 0.22 | F97: =F96/F91 -> 0.22 | G97: =G96/G91 -> 0.22 | H97: =H96/H91 -> 0.22 | I97: =I96/I91 -> 0.22 | J97: =J96/J91 -> 0.22 | K97: =K96/K91 -> 0.22 | L97: =L96/L91 -> 0.22 | ... P97: =P96/P91 -> 0.22
D98: Armário (12%) | E98: ='P & L'!D145 -> 51984 | F98: ='P & L'!E145 -> 54768 | G98: ='P & L'!F145 -> 58464 | H98: ='P & L'!G145 -> 61224 | I98: ='P & L'!H145 -> 64776 | J98: ='P & L'!I145 -> 67380 | K98: ='P & L'!J145 -> 69924 | L98: ='P & L'!K145 -> 72432 | ... P98: ='P & L'!O145 -> 107448
D99: Mesa (10%) | E99: ='P & L'!D146 -> 43320 | F99: ='P & L'!E146 -> 45640 | G99: ='P & L'!F146 -> 48720 | H99: ='P & L'!G146 -> 51020 | I99: ='P & L'!H146 -> 53980 | J99: ='P & L'!I146 -> 56150 | K99: ='P & L'!J146 -> 58270 | L99: ='P & L'!K146 -> 60360 | ... P99: ='P & L'!O146 -> 89540
D100: Conjunto 3 Sala | E100: =SUM(E102:E103) -> 95304 | F100: =SUM(F102:F103) -> 100408 | G100: =SUM(G102:G103) -> 107184 | H100: =SUM(H102:H103) -> 112244 | I100: =SUM(I102:I103) -> 118756 | J100: =SUM(J102:J103) -> 123530 | K100: =SUM(K102:K103) -> 128194 | L100: =SUM(L102:L103) -> 132792 | ... P100: =SUM(P102:P103) -> 196988
D101: % conj 3 / E | E101: =E100/E91 -> 0.22 | F101: =F100/F91 -> 0.22 | G101: =G100/G91 -> 0.22 | H101: =H100/H91 -> 0.22 | I101: =I100/I91 -> 0.22 | J101: =J100/J91 -> 0.22 | K101: =K100/K91 -> 0.22 | L101: =L100/L91 -> 0.22 | ... P101: =P100/P91 -> 0.22
D102: Sofá (12%) | E102: ='P & L'!D148 -> 51984 | F102: ='P & L'!E148 -> 54768 | G102: ='P & L'!F148 -> 58464 | H102: ='P & L'!G148 -> 61224 | I102: ='P & L'!H148 -> 64776 | J102: ='P & L'!I148 -> 67380 | K102: ='P & L'!J148 -> 69924 | L102: ='P & L'!K148 -> 72432 | ... P102: ='P & L'!O148 -> 107448
D103: Painel (10%) | E103: ='P & L'!D149 -> 43320 | F103: ='P & L'!E149 -> 45640 | G103: ='P & L'!F149 -> 48720 | H103: ='P & L'!G149 -> 51020 | I103: ='P & L'!H149 -> 53980 | J103: ='P & L'!I149 -> 56150 | K103: ='P & L'!J149 -> 58270 | L103: ='P & L'!K149 -> 60360 | ... P103: ='P & L'!O149 -> 89540
D104: Conjunto 4 Escritório | E104: =SUM(E106:E107) -> 69312 | F104: =SUM(F106:F107) -> 73024 | G104: =SUM(G106:G107) -> 77952 | H104: =SUM(H106:H107) -> 81632 | I104: =SUM(I106:I107) -> 86368 | J104: =SUM(J106:J107) -> 89840 | K104: =SUM(K106:K107) -> 93232 | L104: =SUM(L106:L107) -> 96576 | ... P104: =SUM(P106:P107) -> 143264
D105: % conj 4 / E | E105: =E104/E91 -> 0.16 | F105: =F104/F91 -> 0.16 | G105: =G104/G91 -> 0.16 | H105: =H104/H91 -> 0.16 | I105: =I104/I91 -> 0.16 | J105: =J104/J91 -> 0.16 | K105: =K104/K91 -> 0.16 | L105: =L104/L91 -> 0.16 | ... P105: =P104/P91 -> 0.16
D106: Mesa de Escritório (9%) | E106: ='P & L'!D151 -> 38988 | F106: ='P & L'!E151 -> 41076 | G106: ='P & L'!F151 -> 43848 | H106: ='P & L'!G151 -> 45918 | I106: ='P & L'!H151 -> 48582 | J106: ='P & L'!I151 -> 50535 | K106: ='P & L'!J151 -> 52443 | L106: ='P & L'!K151 -> 54324 | ... P106: ='P & L'!O151 -> 80586
D107: Cadeira (7%) | E107: ='P & L'!D152 -> 30324 | F107: ='P & L'!E152 -> 31948 | G107: ='P & L'!F152 -> 34104 | H107: ='P & L'!G152 -> 35714 | I107: ='P & L'!H152 -> 37786 | J107: ='P & L'!I152 -> 39305 | K107: ='P & L'!J152 -> 40789 | L107: ='P & L'!K152 -> 42252 | ... P107: ='P & L'!O152 -> 62678
D108: Conjunto 5 Banheiro | E108: =SUM(E110:E111) -> 64980 | F108: =SUM(F110:F111) -> 68460 | G108: =SUM(G110:G111) -> 73080 | H108: =SUM(H110:H111) -> 76530 | I108: =SUM(I110:I111) -> 80970 | J108: =SUM(J110:J111) -> 84225 | K108: =SUM(K110:K111) -> 87405 | L108: =SUM(L110:L111) -> 90540 | ... P108: =SUM(P110:P111) -> 134310
D109: % conj 5 / E | E109: =E108/E91 -> 0.15 | F109: =F108/F91 -> 0.15 | G109: =G108/G91 -> 0.15 | H109: =H108/H91 -> 0.15 | I109: =I108/I91 -> 0.15 | J109: =J108/J91 -> 0.15 | K109: =K108/K91 -> 0.15 | L109: =L108/L91 -> 0.15 | ... P109: =P108/P91 -> 0.15
D110: Gabinete (8%) | E110: ='P & L'!D154 -> 34656 | F110: ='P & L'!E154 -> 36512 | G110: ='P & L'!F154 -> 38976 | H110: ='P & L'!G154 -> 40816 | I110: ='P & L'!H154 -> 43184 | J110: ='P & L'!I154 -> 44920 | K110: ='P & L'!J154 -> 46616 | L110: ='P & L'!K154 -> 48288 | ... P110: ='P & L'!O154 -> 71632
D111: Armarinho (7%) | E111: ='P & L'!D155 -> 30324 | F111: ='P & L'!E155 -> 31948 | G111: ='P & L'!F155 -> 34104 | H111: ='P & L'!G155 -> 35714 | I111: ='P & L'!H155 -> 37786 | J111: ='P & L'!I155 -> 39305 | K111: ='P & L'!J155 -> 40789 | L111: ='P & L'!K155 -> 42252 | ... P111: ='P & L'!O155 -> 62678
D113: giros de estoque anual sobre RL | E113: =(E89*12)/E91 -> 15.235457 | F113: =(F89*12)/F91 -> 15.249781 | G113: =(G89*12)/G91 -> 15.270936 | H113: =(H89*12)/H91 -> 15.523324 | I113: =(I89*12)/I91 -> 15.561319 | J113: =(J89*12)/J91 -> 15.601069 | K113: =(K89*12)/K91 -> 15.651279 | L113: =(L89*12)/L91 -> 15.705765 | ... P113: =(P89*12)/P91 -> 14.473978
D114: (RL*12)/E
D116: giros de estoque anual sobre CMV | E116: =(E90*12)/E91 -> 7.9998414 | F116: =(F90*12)/F91 -> 7.8945828 | G116: =(G90*12)/G91 -> 7.7925983 | H116: =(H90*12)/H91 -> 7.6917801 | I116: =(I90*12)/I91 -> 7.5955265 | J116: =(J90*12)/J91 -> 7.4995507 | K116: =(K90*12)/K91 -> 7.4079379 | L116: =(L90*12)/L91 -> 7.317587 | ... P116: =(P90*12)/P91 -> 6.3155146
...

Sheet SIMULAÇÃO
A1: S
C3: SIMULAÇÃO para próximos 2 anos
D6: ano zero | E6: evolução % para ano 1 | F6: fator | G6: ano 1 | H6: ano 1 / ano zero | I6: evolução % para ano 2 | J6: fator | K6: ano 2 | L6: ano 2 / ano 1 | M6: ano 2 / ano zero | N6: META em 2 anos
C7: ='P & L'!C7 -> Receita Liquida | D7: =SUM('P & L'!D7:O7) -> 9110000 | E7: 0.1 | F7: =1+E7 -> 1.1 | G7: =D7*F7 -> 10021000 | H7: =(G7/D7)-1 -> 0.1 | I7: 0.1 | J7: =1+I7 -> 1.1 | K7: =G7*J7 -> 11023100 | L7: =(K7/G7)-1 -> 0.1 | M7: =(K7/D7)-1 -> 0.21
C10: ='P & L'!C35 -> Custo das Mercadorias vendidas | D10: =SUM('P & L'!D35:O35) -> 4314092.8 | E10: 0.09 | F10: =1+E10 -> 1.09 | G10: =D10*F10 -> 4702361.2 | H10: =(G10/D10)-1 -> 0.09 | I10: 0.09 | J10: =1+I10 -> 1.09 | K10: =G10*J10 -> 5125573.7 | L10: =(K10/G10)-1 -> 0.09 | M10: =(K10/D10)-1 -> 0.1881
C11: CMV / RL | D11: =D10/D7 -> 0.47355574 | G11: =G10/G7 -> 0.46925069 | K11: =K10/K7 -> 0.46498478
C13: ='P & L'!C104 -> Lucro Bruto | D13: =SUM('P & L'!D104:O104) -> 4795907.2 | E13: 0.11 | F13: =1+E13 -> 1.11 | G13: =G7-G10 -> 5318638.8 | H13: =(G13/D13)-1 -> 0.10899536 | I13: 0.11 | J13: =1+I13 -> 1.11 | K13: =K7-K10 -> 5897526.3 | L13: =(K13/G13)-1 -> 0.10884129 | M13: =(K13/D13)-1 -> 0.22969985
C14: LB / RL | D14: =D13/D7 -> 0.52644426 | G14: =G13/G7 -> 0.53074931 | K14: =K13/K7 -> 0.53501522
C16: ='P & L'!C115 -> Despesas Administrativas | D16: =SUM('P & L'!D115:O115) -> 1548700 | E16: 0.09 | F16: =1+E16 -> 1.09 | G16: =D16*F16 -> 1688083 | H16: =(G16/D16)-1 -> 0.09 | I16: 0.08 | J16: =1+I16 -> 1.08 | K16: =G16*J16 -> 1823129.6 | L16: =(K16/G16)-1 -> 0.08 | M16: =(K16/D16)-1 -> 0.1772
C17: DA / RL | D17: =D16/D7 -> 0.17 | G17: =G16/G7 -> 0.16845455 | K17: =K16/K7 -> 0.16539174
C19: ='P & L'!C122 -> Despesas Comerciais | D19: =SUM('P & L'!D122:O122) -> 1184300 | E19: 0.1 | F19: =1+E19 -> 1.1 | G19: =D19*F19 -> 1302730 | H19: =(G19/D19)-1 -> 0.1 | I19: 0.09 | J19: =1+I19 -> 1.09 | K19: =G19*J19 -> 1419975.7 | L19: =(K19/G19)-1 -> 0.09 | M19: =(K19/D19)-1 -> 0.199
C20: DC / RL | D20: =D19/D7 -> 0.13 | G20: =G19/G7 -> 0.13 | K20: =K19/K7 -> 0.12881818
C22: ='P & L'!C130 -> Outras despesas / receitas | D22: =SUM('P & L'!D130:O130) -> 23550 | E22: 0.05 | F22: =1+E22 -> 1.05 | G22: =D22*F22 -> 24727.5 | H22: =(G22/D22)-1 -> 0.05 | I22: 0.05 | J22: =1+I22 -> 1.05 | K22: =G22*J22 -> 25963.875 | L22: =(K22/G22)-1 -> 0.05 | M22: =(K22/D22)-1 -> 0.1025
C23: or / RL | D23: =D22/D7 -> 0.0025850714 | G23: =G22/G7 -> 0.0024675681 | K23: =K22/K7 -> 0.0023554059
C25: ='P & L'!C136 -> Lucro Liquido | D25: =SUM('P & L'!D136:O136) -> 2086457.2 | E25: 0.11 | F25: =1+E25 -> 1.11 | G25: =G13-G16-G19-G22 -> 2303098.3 | H25: =(G25/D25)-1 -> 0.10383206 | I25: 0.12 | J25: =1+I25 -> 1.12 | K25: =K13-K16-K19-K22 -> 2628457.1 | L25: =(K25/G25)-1 -> 0.14127003 | M25: =(K25/D25)-1 -> 0.25977045 | N25: 0.2
C26: LL / RL | D26: =D25/D7 -> 0.22902933 | G26: =G25/G7 -> 0.2298272 | K26: =K25/K7 -> 0.2384499
C30: ='P & L'!C139 -> Estoques | D30: =SUM('P & L'!D139:O139) -> 7091200 | E30: 0.02 | F30: =1+E30 -> 1.02 | G30: =D30*F30 -> 7233024 | H30: =(G30/D30)-1 -> 0.02 | I30: 0.03 | J30: =1+I30 -> 1.03 | K30: =G30*J30 -> 7450014.7 | L30: =(K30/G30)-1 -> 0.03 | M30: =(K30/D30)-1 -> 0.0506
C31: giro medio sobre CMV | D31: =D10/(D30/12) -> 7.300473 | G31: =G10/(G30/12) -> 7.8014858 | H31: =(G31/D31)-1 -> 0.068627451 | K31: =K10/(K30/12) -> 8.2559413 | L31: =(K31/G31)-1 -> 0.058252427 | M31: =(K31/D31)-1 -> 0.13087759 | N31: 7

Sheet ORÇAMENTO 3 anos
M2: ANO ZERO | N2: ANO 1 | Y2: ANO 1 | Z2: ANO 2 | AK2: ANO 2
A3: Descrição | B3: jan | C3: fev | D3: mar | E3: abr | F3: mai | G3: jun | H3: jul | I3: ago | J3: set | K3: out | L3: nov | M3: dez | N3: jan | O3: fev | P3: mar | Q3: abr | R3: mai | S3: jun | T3: jul | U3: ago | V3: set | W3: out | X3: nov | Y3: dez | Z3: jan | AA3: fev | AB3: mar | AC3: abr | AD3: mai | AE3: jun | AF3: jul | AG3: ago | AH3: set | AI3: out | AJ3: nov | AK3: dez
A5: Receita Liquida | B5: =B7 -> 550000 | C5: =C7 -> 580000 | D5: =D7 -> 620000 | E5: =E7 -> 660000 | F5: =F7 -> 700000 | G5: =G7 -> 730000 | H5: =H7 -> 760000 | I5: =I7 -> 790000 | ... AK5: =AK7 -> 1306800
N6: 1.1 | Z6: 1.1
A7: area | B7: =SUM(B8:B13) -> 550000 | C7: =SUM(C8:C13) -> 580000 | D7: =SUM(D8:D13) -> 620000 | E7: =SUM(E8:E13) -> 660000 | F7: =SUM(F8:F13) -> 700000 | G7: =SUM(G8:G13) -> 730000 | H7: =SUM(H8:H13) -> 760000 | I7: =SUM(I8:I13) -> 790000 | ... M7: =SUM(M8:M13) -> 1080000 | N7: =SUM(N8:N12) -> 605000 | O7: =SUM(O8:O13) -> 638000 | P7: =SUM(P8:P13) -> 682000 | Q7: =SUM(Q8:Q13) -> 726000 | R7: =SUM(R8:R13) -> 770000 | S7: =SUM(S8:S13) -> 803000 | T7: =SUM(T8:T13) -> 836000 | U7: =SUM(U8:U13) -> 869000 | V7: =SUM(V8:V13) -> 902000 | ... Y7: =SUM(Y8:Y13) -> 1188000 | Z7: =SUM(Z8:Z12) -> 665500 | AA7: =SUM(AA8:AA13) -> 701800 | AB7: =SUM(AB8:AB13) -> 750200 | AC7: =SUM(AC8:AC13) -> 798600 | AD7: =SUM(AD8:AD13) -> 847000 | AE7: =SUM(AE8:AE13) -> 883300 | AF7: =SUM(AF8:AF13) -> 919600 | AG7: =SUM(AG8:AG13) -> 955900 | AH7: =SUM(AH8:AH13) -> 992200 | ... AK7: =SUM(AK8:AK13) -> 1306800
A8: Aparecida | B8: 70000 | C8: 75000 | D8: 80000 | E8: 85000 | F8: 90000 | G8: 95000 | H8: 100000 | I8: 105000 | J8: 110000 | K8: 120000 | L8: 130000 | M8: 150000 | N8: =B8*$N$6 -> 77000 | O8: =C8*$N$6 -> 82500 | P8: =D8*$N$6 -> 88000 | Q8: =E8*$N$6 -> 93500 | R8: =F8*$N$6 -> 99000 | S8: =G8*$N$6 -> 104500 | T8: =H8*$N$6 -> 110000 | U8: =I8*$N$6 -> 115500 | ... Y8: =M8*$N$6 -> 165000 | Z8: =N8*$Z$6 -> 84700 | AA8: =O8*$N$6 -> 90750 | AB8: =P8*$N$6 -> 96800 | AC8: =Q8*$N$6 -> 102850 | AD8: =R8*$N$6 -> 108900 | AE8: =S8*$N$6 -> 114950 | AF8: =T8*$N$6 -> 121000 | AG8: =U8*$N$6 -> 127050 | AH8: =V8*$N$6 -> 133100 | ... AK8: =Y8*$N$6 -> 181500
A9: Caçapava | B9: 80000 | C9: 85000 | D9: 90000 | E9: 95000 | F9: 100000 | G9: 105000 | H9: 110000 | I9: 115000 | J9: 120000 | K9: 130000 | L9: 140000 | M9: 160000 | N9: =B9*$N$6 -> 88000 | O9: =C9*$N$6 -> 93500 | P9: =D9*$N$6 -> 99000 | Q9: =E9*$N$6 -> 104500 | R9: =F9*$N$6 -> 110000 | S9: =G9*$N$6 -> 115500 | T9: =H9*$N$6 -> 121000 | U9: =I9*$N$6 -> 126500 | ... AK9: =Y9*$N$6 -> 193600
A10: Jacarei | B10: 120000 | C10: 125000 | D10: 130000 | E10: 140000 | F10: 150000 | G10: 155000 | H10: 160000 | I10: 165000 | J10: 170000 | K10: 180000 | L10: 200000 | M10: 220000 | N10: =B10*$N$6 -> 132000 | O10: =C10*$N$6 -> 137500 | P10: =D10*$N$6 -> 143000 | Q10: =E10*$N$6 -> 154000 | R10: =F10*$N$6 -> 165000 | S10: =G10*$N$6 -> 170500 | T10: =H10*$N$6 -> 176000 | U10: =I10*$N$6 -> 181500 | ... AK10: =Y10*$N$6 -> 266200
A11: SJC | B11: 180000 | C11: 190000 | D11: 210000 | E11: 220000 | F11: 230000 | G11: 240000 | H11: 250000 | I11: 260000 | J11: 270000 | K11: 280000 | L11: 300000 | M11: 350000 | N11: =B11*$N$6 -> 198000 | O11: =C11*$N$6 -> 209000 | P11: =D11*$N$6 -> 231000 | Q11: =E11*$N$6 -> 242000 | R11: =F11*$N$6 -> 253000 | S11: =G11*$N$6 -> 264000 | T11: =H11*$N$6 -> 275000 | U11: =I11*$N$6 -> 286000 | ... AK11: =Y11*$N$6 -> 423500
A12: Taubaté | B12: 100000 | C12: 105000 | D12: 110000 | E12: 120000 | F12: 130000 | G12: 135000 | H12: 140000 | I12: 145000 | J12: 150000 | K12: 160000 | L12: 180000 | M12: 200000 | N12: =B12*$N$6 -> 110000 | O12: =C12*$N$6 -> 115500 | P12: =D12*$N$6 -> 121000 | Q12: =E12*$N$6 -> 132000 | R12: =F12*$N$6 -> 143000 | S12: =G12*$N$6 -> 148500 | T12: =H12*$N$6 -> 154000 | U12: =I12*$N$6 -> 159500 | ... AK12: =Y12*$N$6 -> 242000
N13: =N6 -> 1.1 | Z13: =Z6 -> 1.1
A14: canais | B14: =SUM(B15:B17) -> 550000 | C14: =SUM(C15:C17) -> 580000 | D14: =SUM(D15:D17) -> 620000 | E14: =SUM(E15:E17) -> 660000 | F14: =SUM(F15:F17) -> 700000 | G14: =SUM(G15:G17) -> 730000 | H14: =SUM(H15:H17) -> 760000 | I14: =SUM(I15:I17) -> 790000 | ... AK14: =SUM(AK15:AK17) -> 1306800
A15: diretas | B15: 275000 | C15: 290000 | D15: 310000 | E15: 330000 | F15: 350000 | G15: 365000 | H15: 380000 | I15: 395000 | J15: 410000 | K15: 435000 | L15: 475000 | M15: 540000 | N15: =B15*$N$13 -> 302500 | O15: =C15*$N$13 -> 319000 | P15: =D15*$N$13 -> 341000 | Q15: =E15*$N$13 -> 363000 | R15: =F15*$N$13 -> 385000 | S15: =G15*$N$13 -> 401500 | T15: =H15*$N$13 -> 418000 | U15: =I15*$N$13 -> 434500 | ... Y15: =M15*$N$13 -> 594000 | Z15: =N15*$Z$13 -> 332750 | AA15: =O15*$N$13 -> 350900 | AB15: =P15*$N$13 -> 375100 | AC15: =Q15*$N$13 -> 399300 | AD15: =R15*$N$13 -> 423500 | AE15: =S15*$N$13 -> 441650 | AF15: =T15*$N$13 -> 459800 | AG15: =U15*$N$13 -> 477950 | AH15: =V15*$N$13 -> 496100 | ... AK15: =Y15*$N$13 -> 653400
A16: e-comerce | B16: 165000 | C16: 174000 | D16: 186000 | E16: 198000 | F16: 210000 | G16: 219000 | H16: 228000 | I16: 237000 | J16: 246000 | K16: 261000 | L16: 285000 | M16: 324000 | N16: =B16*$N$13 -> 181500 | O16: =C16*$N$13 -> 191400 | P16: =D16*$N$13 -> 204600 | Q16: =E16*$N$13 -> 217800 | R16: =F16*$N$13 -> 231000 | S16: =G16*$N$13 -> 240900 | T16: =H16*$N$13 -> 250800 | U16: =I16*$N$13 -> 260700 | ... AK16: =Y16*$N$13 -> 392040
A17: representantes | B17: 110000 | C17: 116000 | D17: 124000 | E17: 132000 | F17: 140000 | G17: 146000 | H17: 152000 | I17: 158000 | J17: 164000 | K17: 174000 | L17: 190000 | M17: 216000 | N17: =B17*$N$13 -> 121000 | O17: =C17*$N$13 -> 127600 | P17: =D17*$N$13 -> 136400 | Q17: =E17*$N$13 -> 145200 | R17: =F17*$N$13 -> 154000 | S17: =G17*$N$13 -> 160600 | T17: =H17*$N$13 -> 167200 | U17: =I17*$N$13 -> 173800 | ... AK17: =Y17*$N$13 -> 261360
N18: =N6 -> 1.1 | Z18: =Z6 -> 1.1
A19: produtos | B19: =SUM(B20:B24) -> 550000 | C19: =SUM(C20:C24) -> 580000 | D19: =SUM(D20:D24) -> 620000 | E19: =SUM(E20:E24) -> 660000 | F19: =SUM(F20:F24) -> 700000 | G19: =SUM(G20:G24) -> 730000 | H19: =SUM(H20:H24) -> 760000 | I19: =SUM(I20:I24) -> 790000 | ... AK19: =SUM(AK20:AK24) -> 1306800
A20: Conjunto 1 Quarto | B20: 165000 | C20: 174000 | D20: 186000 | E20: 198000 | F20: 210000 | G20: 219000 | H20: 228000 | I20: 237000 | J20: 246000 | K20: 261000 | L20: 285000 | M20: 324000 | N20: =B20*$N$18 -> 181500 | O20: =C20*$N$18 -> 191400 | P20: =D20*$N$18 -> 204600 | Q20: =E20*$N$18 -> 217800 | R20: =F20*$N$18 -> 231000 | S20: =G20*$N$18 -> 240900 | T20: =H20*$N$18 -> 250800 | U20: =I20*$N$18 -> 260700 | ... Y20: =M20*$N$18 -> 356400 | Z20: =N20*$Z$18 -> 199650 | AA20: =O20*$N$18 -> 210540 | AB20: =P20*$N$18 -> 225060 | AC20: =Q20*$N$18 -> 239580 | AD20: =R20*$N$18 -> 254100 | AE20: =S20*$N$18 -> 264990 | AF20: =T20*$N$18 -> 275880 | AG20: =U20*$N$18 -> 286770 | AH20: =V20*$N$18 -> 297660 | ... AK20: =Y20*$N$18 -> 392040
A21: Conjunto 2 Cozinha | B21: 137500 | C21: 145000 | D21: 155000 | E21: 165000 | F21: 175000 | G21: 182500 | H21: 190000 | I21: 197500 | J21: 205000 | K21: 217500 | L21: 237500 | M21: 270000 | N21: =B21*$N$18 -> 151250 | O21: =C21*$N$18 -> 159500 | P21: =D21*$N$18 -> 170500 | Q21: =E21*$N$18 -> 181500 | R21: =F21*$N$18 -> 192500 | S21: =G21*$N$18 -> 200750 | T21: =H21*$N$18 -> 209000 | U21: =I21*$N$18 -> 217250 | ... AK21: =Y21*$N$18 -> 326700
A22: Conjunto 3 Sala | B22: 137500 | C22: 145000 | D22: 155000 | E22: 165000 | F22: 175000 | G22: 182500 | H22: 190000 | I22: 197500 | J22: 205000 | K22: 217500 | L22: 237500 | M22: 270000 | N22: =B22*$N$18 -> 151250 | O22: =C22*$N$18 -> 159500 | P22: =D22*$N$18 -> 170500 | Q22: =E22*$N$18 -> 181500 | R22: =F22*$N$18 -> 192500 | S22: =G22*$N$18 -> 200750 | T22: =H22*$N$18 -> 209000 | U22: =I22*$N$18 -> 217250 | ... AK22: =Y22*$N$18 -> 326700
A23: Conjunto 4 Escritório | B23: 55000 | C23: 58000 | D23: 62000 | E23: 66000 | F23: 70000 | G23: 73000 | H23: 76000 | I23: 79000 | J23: 82000 | K23: 87000 | L23: 95000 | M23: 108000 | N23: =B23*$N$18 -> 60500 | O23: =C23*$N$18 -> 63800 | P23: =D23*$N$18 -> 68200 | Q23: =E23*$N$18 -> 72600 | R23: =F23*$N$18 -> 77000 | S23: =G23*$N$18 -> 80300 | T23: =H23*$N$18 -> 83600 | U23: =I23*$N$18 -> 86900 | ... AK23: =Y23*$N$18 -> 130680
A24: Conjunto 5 Banheiro | B24: 55000 | C24: 58000 | D24: 62000 | E24: 66000 | F24: 70000 | G24: 73000 | H24: 76000 | I24: 79000 | J24: 82000 | K24: 87000 | L24: 95000 | M24: 108000 | N24: =B24*$N$18 -> 60500 | O24: =C24*$N$18 -> 63800 | P24: =D24*$N$18 -> 68200 | Q24: =E24*$N$18 -> 72600 | R24: =F24*$N$18 -> 77000 | S24: =G24*$N$18 -> 80300 | T24: =H24*$N$18 -> 83600 | U24: =I24*$N$18 -> 86900 | ... AK24: =Y24*$N$18 -> 130680
A26: qualificação | B26: =SUM(B27:B27) -> 0 | C26: =SUM(C27:C27) -> 0 | D26: =SUM(D27:D27) -> 0 | E26: =SUM(E27:E27) -> 0 | F26: =SUM(F27:F27) -> 0 | G26: =SUM(G27:G27) -> 0 | H26: =SUM(H27:H27) -> 0 | I26: =SUM(I27:I27) -> 0 | ... AK26: =SUM(AK27:AK27) -> 0.42843847
M27: =M28/M5 -> 0.43633578 | N27: 1.09 | Y27: =Y28/Y5 -> 0.4323691 | Z27: 1.09 | AK27: =AK28/AK5 -> 0.42843847
A28: custo das mercadorias vendidas | B28: =B31+B34+B37+B40+B43 -> 288794.28 | C28: =C31+C34+C37+C40+C43 -> 300257.3 | D28: =D31+D34+D37+D40+D43 -> 316379.49 | E28: =E31+E34+E37+E40+E43 -> 327028.85 | F28: =F31+F34+F37+F40+F43 -> 341672.1 | G28: =G31+G34+G37+G40+G43 -> 350916.47 | H28: =H31+H34+H37+H40+H43 -> 359717.12 | I28: =I31+I34+I37+I40+I43 -> 368074.63 | ... AK28: =AK31+AK34+AK37+AK40+AK43 -> 559883.39
A30: produtos | B30: =B31+B34+B37+B40+B43 -> 288794.28 | C30: =C31+C34+C37+C40+C43 -> 300257.3 | D30: =D31+D34+D37+D40+D43 -> 316379.49 | E30: =E31+E34+E37+E40+E43 -> 327028.85 | F30: =F31+F34+F37+F40+F43 -> 341672.1 | G30: =G31+G34+G37+G40+G43 -> 350916.47 | H30: =H31+H34+H37+H40+H43 -> 359717.12 | I30: =I31+I34+I37+I40+I43 -> 368074.63 | ... AK30: =AK31+AK34+AK37+AK40+AK43 -> 559883.39
A31: Conjunto 1 Quarto | B31: =SUM(B32:B33) -> 86638.283 | C31: =SUM(C32:C33) -> 90077.19 | D31: =SUM(D32:D33) -> 94913.847 | E31: =SUM(E32:E33) -> 98108.703 | F31: =SUM(F32:F33) -> 102501.63 | G31: =SUM(G32:G33) -> 105274.94 | H31: =SUM(H32:H33) -> 107915.14 | I31: =SUM(I32:I33) -> 110422.22 | ... AK31: =SUM(AK32:AK33) -> 167964.52
A32: Guarda Roupas | B32: 51982.97 | C32: 54046.314 | D32: 56948.308 | E32: 58865.222 | F32: 61500.978 | G32: 63164.965 | H32: 64749.082 | I32: 66253.326 | J32: 67677.7 | K32: 70646.253 | L32: 75877.83 | M32: 84823.427 | N32: =B32*$N$27 -> 56661.437 | O32: =C32*$N$27 -> 58910.482 | P32: =D32*$N$27 -> 62073.656 | Q32: =E32*$N$27 -> 64163.092 | R32: =F32*$N$27 -> 67036.066 | S32: =G32*$N$27 -> 68849.812 | T32: =H32*$N$27 -> 70576.499 | U32: =I32*$N$27 -> 72216.126 | ... Y32: =M32*$N$27 -> 92457.535 | Z32: =N32*$Z$27 -> 61760.966 | AA32: =O32*$N$27 -> 64212.426 | AB32: =P32*$N$27 -> 67660.285 | AC32: =Q32*$N$27 -> 69937.77 | AD32: =R32*$N$27 -> 73069.312 | AE32: =S32*$N$27 -> 75046.296 | AF32: =T32*$N$27 -> 76928.384 | AG32: =U32*$N$27 -> 78715.577 | AH32: =V32*$N$27 -> 80407.875 | ... AK32: =Y32*$N$27 -> 100778.71
A33: Cama | B33: 34655.313 | C33: 36030.876 | D33: 37965.539 | E33: 39243.481 | F33: 41000.652 | G33: 42109.977 | H33: 43166.054 | I33: 44168.897 | J33: 45118.496 | K33: 47097.502 | L33: 50585.22 | M33: 56548.951 | N33: =B33*$N$27 -> 37774.291 | O33: =C33*$N$27 -> 39273.655 | P33: =D33*$N$27 -> 41382.437 | Q33: =E33*$N$27 -> 42775.395 | R33: =F33*$N$27 -> 44690.711 | S33: =G33*$N$27 -> 45899.875 | T33: =H33*$N$27 -> 47050.999 | U33: =I33*$N$27 -> 48144.098 | ... AK33: =Y33*$N$27 -> 67185.809
A34: Conjunto 2 Cozinha | B34: =SUM(B35:B36) -> 72198.569 | C34: =SUM(C35:C36) -> 75064.325 | D34: =SUM(D35:D36) -> 79094.872 | E34: =SUM(E35:E36) -> 81757.253 | F34: =SUM(F35:F36) -> 85418.025 | G34: =SUM(G35:G36) -> 87729.119 | H34: =SUM(H35:H36) -> 89929.28 | I34: =SUM(I35:I36) -> 92018.942 | ... AK34: =SUM(AK35:AK36) -> 139970.44
A35: Armário | B35: 43319.141 | C35: 45038.595 | D35: 47456.924 | E35: 49054.351 | F35: 51250.815 | G35: 52637.471 | H35: 53957.568 | I35: 55211.539 | J35: 56398.083 | K35: 58871.878 | L35: 63231.525 | M35: 70686.189 | N35: =B35*$N$27 -> 47217.864 | O35: =C35*$N$27 -> 49092.069 | P35: =D35*$N$27 -> 51728.047 | Q35: =E35*$N$27 -> 53469.243 | R35: =F35*$N$27 -> 55863.388 | S35: =G35*$N$27 -> 57374.844 | T35: =H35*$N$27 -> 58813.749 | U35: =I35*$N$27 -> 60180.577 | ... AK35: =Y35*$N$27 -> 83982.261
A36: Mesa | B36: 28879.427 | C36: 30025.73 | D36: 31637.949 | E36: 32702.901 | F36: 34167.21 | G36: 35091.647 | H36: 35971.712 | I36: 36807.404 | J36: 37598.722 | K36: 39247.918 | L36: 42154.35 | M36: 47124.126 | N36: =B36*$N$27 -> 31478.576 | O36: =C36*$N$27 -> 32728.046 | P36: =D36*$N$27 -> 34485.364 | Q36: =E36*$N$27 -> 35646.162 | R36: =F36*$N$27 -> 37242.259 | S36: =G36*$N$27 -> 38249.896 | T36: =H36*$N$27 -> 39209.166 | U36: =I36*$N$27 -> 40120.07 | ... AK36: =Y36*$N$27 -> 55988.174
A37: Conjunto 3 Sala | B37: =SUM(B38:B39) -> 72198.569 | C37: =SUM(C38:C39) -> 75064.325 | D37: =SUM(D38:D39) -> 79094.872 | E37: =SUM(E38:E39) -> 81757.253 | F37: =SUM(F38:F39) -> 85418.025 | G37: =SUM(G38:G39) -> 87729.119 | H37: =SUM(H38:H39) -> 89929.28 | I37: =SUM(I38:I39) -> 92018.942 | ... AK37: =SUM(AK38:AK39) -> 139970.44
A38: Sofá | B38: 43319.141 | C38: 45038.595 | D38: 47456.924 | E38: 49054.351 | F38: 51250.815 | G38: 52637.471 | H38: 53957.568 | I38: 55211.539 | J38: 56398.083 | K38: 58871.878 | L38: 63231.525 | M38: 70686.189 | N38: =B38*$N$27 -> 47217.864 | O38: =C38*$N$27 -> 49092.069 | P38: =D38*$N$27 -> 51728.047 | Q38: =E38*$N$27 -> 53469.243 | R38: =F38*$N$27 -> 55863.388 | S38: =G38*$N$27 -> 57374.844 | T38: =H38*$N$27 -> 58813.749 | U38: =I38*$N$27 -> 60180.577 | ... AK38: =Y38*$N$27 -> 83982.261
A39: Painel | B39: 28879.427 | C39: 30025.73 | D39: 31637.949 | E39: 32702.901 | F39: 34167.21 | G39: 35091.647 | H39: 35971.712 | I39: 36807.404 | J39: 37598.722 | K39: 39247.918 | L39: 42154.35 | M39: 47124.126 | N39: =B39*$N$27 -> 31478.576 | O39: =C39*$N$27 -> 32728.046 | P39: =D39*$N$27 -> 34485.364 | Q39: =E39*$N$27 -> 35646.162 | R39: =F39*$N$27 -> 37242.259 | S39: =G39*$N$27 -> 38249.896 | T39: =H39*$N$27 -> 39209.166 | U39: =I39*$N$27 -> 40120.07 | ... AK39: =Y39*$N$27 -> 55988.174
A40: Conjunto 4 Escritório | B40: =SUM(B41:B42) -> 28879.427 | C40: =SUM(C41:C42) -> 30025.73 | D40: =SUM(D41:D42) -> 31637.949 | E40: =SUM(E41:E42) -> 32702.821 | F40: =SUM(F41:F42) -> 34167.21 | G40: =SUM(G41:G42) -> 35091.647 | H40: =SUM(H41:H42) -> 35971.712 | I40: =SUM(I41:I42) -> 36807.259 | ... AK40: =SUM(AK41:AK42) -> 55988.998
A41: Mesa de Escritório | B41: 17327.657 | C41: 18015.438 | D41: 18982.769 | E41: 19621.741 | F41: 20500.326 | G41: 21054.988 | H41: 21583.027 | I41: 22084.298 | J41: 22559.233 | K41: 23548.751 | L41: 25292.61 | M41: 28275.169 | N41: =B41*$N$27 -> 18887.146 | O41: =C41*$N$27 -> 19636.827 | P41: =D41*$N$27 -> 20691.219 | Q41: =E41*$N$27 -> 21387.697 | R41: =F41*$N$27 -> 22345.355 | S41: =G41*$N$27 -> 22949.937 | T41: =H41*$N$27 -> 23525.5 | U41: =I41*$N$27 -> 24071.884 | ... AK41: =Y41*$N$27 -> 33593.729
A42: Cadeira | B42: 11551.771 | C42: 12010.292 | D42: 12655.18 | E42: 13081.08 | F42: 13666.884 | G42: 14036.659 | H42: 14388.685 | I42: 14722.961 | J42: 15039.489 | K42: 15699.167 | L42: 16861.74 | M42: 18849.65 | N42: =B42*$N$27 -> 12591.43 | O42: =C42*$N$27 -> 13091.218 | P42: =D42*$N$27 -> 13794.146 | Q42: =E42*$N$27 -> 14258.377 | R42: =F42*$N$27 -> 14896.904 | S42: =G42*$N$27 -> 15299.958 | T42: =H42*$N$27 -> 15683.666 | U42: =I42*$N$27 -> 16048.028 | ... AK42: =Y42*$N$27 -> 22395.27
A43: Conjunto 5 Banheiro | B43: =SUM(B44:B45) -> 28879.427 | C43: =SUM(C44:C45) -> 30025.73 | D43: =SUM(D44:D45) -> 31637.949 | E43: =SUM(E44:E45) -> 32702.821 | F43: =SUM(F44:F45) -> 34167.21 | G43: =SUM(G44:G45) -> 35091.647 | H43: =SUM(H44:H45) -> 35971.712 | I43: =SUM(I44:I45) -> 36807.259 | ... AK43: =SUM(AK44:AK45) -> 55988.998
A44: Gabinete | B44: 17327.657 | C44: 18015.438 | D44: 18982.769 | E44: 19621.741 | F44: 20500.326 | G44: 21054.988 | H44: 21583.027 | I44: 22084.298 | J44: 22559.233 | K44: 23548.751 | L44: 25292.61 | M44: 28275.169 | N44: =B44*$N$27 -> 18887.146 | O44: =C44*$N$27 -> 19636.827 | P44: =D44*$N$27 -> 20691.219 | Q44: =E44*$N$27 -> 21387.697 | R44: =F44*$N$27 -> 22345.355 | S44: =G44*$N$27 -> 22949.937 | T44: =H44*$N$27 -> 23525.5 | U44: =I44*$N$27 -> 24071.884 | ... AK44: =Y44*$N$27 -> 33593.729
...
